<?xml version="1.0" ?>
<robot name="Robot">
  <!--Generated by RobotCAD, a ROS Workbench for FreeCAD (https://github.com/drfenixion/freecad.robotcad)-->
  <link name="wheel_fl">
    <visual>
      <!--60X45 wheel002/Part__Feature001.-->
      <origin rpy="-3.141592653589793 -1.5707963267948963 0" xyz="-0.004 -0.182 -0.012"/>
      <geometry>
        <mesh filename="package://sucker/meshes/wheel_fl.STL"/>
      </geometry>
    </visual>
    <collision>
      <!--bound_obj__wheel_fl001__col__0X45_wheel__BoundCylinder/col__0X45_wheel__BoundCylinder.-->
      <origin rpy="0 0 -3.141592653589793" xyz="0.0 0.0 0.0225"/>
      <geometry>
        <cylinder length="0.045" radius="0.031"/>
      </geometry>
    </collision>
    <inertial>
      <mass value="0.10137086152150322"/>
      <origin rpy="-3.141592653589793 -1.5707963267948963 0" xyz="0.0 0.0 0.0197725"/>
      <inertia ixx="5.419874056564316e-05" ixy="-4.757650910246266e-16" ixz="4.612832764325445e-16" iyy="4.089318376860958e-05" iyz="-2.2117179469207724e-19" izz="4.089318376860995e-05"/>
    </inertial>
  </link>
  <link name="wheel_rr">
    <visual>
      <!--mirror_Wheel_Sucker/_0X45_wheel001.Part__Feature006.-->
      <origin rpy="1.5707963267948961 -1.5707963267948957 0" xyz="-0.03 0.004 0.128"/>
      <geometry>
        <mesh filename="package://sucker/meshes/wheel_rr.STL"/>
      </geometry>
    </visual>
    <collision>
      <!--bound_obj__wheel_rr001__col_mirror_Wheel_Sucker__BoundCylinder/col_mirror_Wheel_Sucker__BoundCylinder.-->
      <origin rpy="0 0 1.5707963267948963" xyz="0.0 0.0 -0.0225"/>
      <geometry>
        <cylinder length="0.045" radius="0.031"/>
      </geometry>
    </collision>
    <inertial>
      <mass value="0.1013708615215032"/>
      <origin rpy="1.5707963267948961 -1.5707963267948957 0" xyz="0.0 0.0 -0.0197725"/>
      <inertia ixx="5.419874056564317e-05" ixy="-4.757807767681403e-16" ixz="-4.612891688394715e-16" iyy="4.0893183768609606e-05" iyz="2.1150030079300045e-19" izz="4.089318376860996e-05"/>
    </inertial>
  </link>
  <link name="wheel_fr">
    <visual>
      <!--mirror_Wheel_Sucker001/_0X45_wheel002.Part__Feature011.-->
      <origin rpy="0 1.5707963267948963 0" xyz="-0.004 0.03 -0.128"/>
      <geometry>
        <mesh filename="package://sucker/meshes/wheel_fr.STL"/>
      </geometry>
    </visual>
    <collision>
      <!--bound_obj__wheel_fr001__col_mirror_Wheel_Sucker001__BoundCylinder/col_mirror_Wheel_Sucker001__BoundCylinder.-->
      <origin rpy="3.141592653589793 0 -3.141592653589793" xyz="0.0 0.0 0.0225"/>
      <geometry>
        <cylinder length="0.045" radius="0.031"/>
      </geometry>
    </collision>
    <inertial>
      <mass value="0.1013708615215032"/>
      <origin rpy="0 1.5707963267948963 0" xyz="0.0 0.0 0.0197725"/>
      <inertia ixx="5.419874056564317e-05" ixy="-4.757807767681403e-16" ixz="-4.612891688394715e-16" iyy="4.0893183768609606e-05" iyz="2.1150030079300045e-19" izz="4.089318376860996e-05"/>
    </inertial>
  </link>
  <link name="wheel_rl">
    <visual>
      <!--60X45 wheel011/Part__Feature016.-->
      <origin rpy="-3.141592653589793 -1.5707963267948963 0" xyz="-0.004 -0.03 -0.012"/>
      <geometry>
        <mesh filename="package://sucker/meshes/wheel_rl.STL"/>
      </geometry>
    </visual>
    <collision>
      <!--bound_obj__wheel_rl001__col__0X45_wheel003__BoundCylinder/col__0X45_wheel003__BoundCylinder.-->
      <origin rpy="0 0 -3.141592653589793" xyz="0.0 0.0 0.0225"/>
      <geometry>
        <cylinder length="0.045" radius="0.031"/>
      </geometry>
    </collision>
    <inertial>
      <mass value="0.1013708615215032"/>
      <origin rpy="-3.141592653589793 -1.5707963267948963 0" xyz="0.0 0.0 0.0197725"/>
      <inertia ixx="5.419874056564313e-05" ixy="-4.75772369506694e-16" ixz="4.612744819877912e-16" iyy="4.0893183768609565e-05" iyz="-2.177397254854674e-19" izz="4.089318376860993e-05"/>
    </inertial>
  </link>
  <link name="base_link">
    <visual>
      <!--Base/Fusion003.-->
      <origin rpy="0 0 0" xyz="0.0 0.0 0.0"/>
      <geometry>
        <mesh filename="package://sucker/meshes/base_link.STL"/>
      </geometry>
    </visual>
    <collision>
      <!--bound_obj__base_link__col_Pidar__BoundBox/col_Pidar__BoundBox.-->
      <origin rpy="0 0 0" xyz="0.5 0.417654 0.545581"/>
      <geometry>
        <box size="0.1580000000000001 0.23130676148971577 0.129837188733113"/>
      </geometry>
    </collision>
    <inertial>
      <mass value="0.8083600000000001"/>
      <origin rpy="0 0 0" xyz="0.500116 0.42552 0.517151"/>
      <inertia ixx="0.001486864359911436" ixy="-1.4589308519551736e-05" ixz="-2.5478097583648844e-06" iyy="0.0006762102489574196" iyz="-0.00028400129847747476" izz="0.0014875077634902243"/>
    </inertial>
  </link>
  <link name="camera">
    <visual>
      <!--Cumera001/Part__Feature037.-->
      <origin rpy="0 0 0" xyz="0.0 -0.013 -0.1055"/>
      <geometry>
        <mesh filename="package://sucker/meshes/camera.STL"/>
      </geometry>
    </visual>
    <collision>
      <!--bound_obj__camera__col_Cumera__BoundBox/col_Cumera__BoundBox.-->
      <origin rpy="0 0 0" xyz="0.0 -0.0025 0.01"/>
      <geometry>
        <box size="0.05 0.007 0.02"/>
      </geometry>
    </collision>
    <inertial>
      <mass value="0.002536261026600647"/>
      <origin rpy="0 0 0" xyz="0.0 -0.000574434 0.01"/>
      <inertia ixx="7.910553265377342e-08" ixy="1.7220902811905667e-24" ixz="1.0213057066721374e-23" iyy="5.175376561658415e-07" iyz="2.1209416445344687e-23" izz="4.501055326537734e-07"/>
    </inertial>
  </link>
  <link name="lidar">
    <visual>
      <!--Fusion003-->
      <origin rpy="-3.141592653589793 0 0" xyz="0.0 -0.065 0.059"/>
      <geometry>
        <mesh filename="package://sucker/meshes/lidar.STL"/>
      </geometry>
    </visual>
    <visual>
      <!--lidar/Part__Feature036.-->
      <origin rpy="-3.141592653589793 0 0" xyz="0.0 -0.065 0.059"/>
      <geometry>
        <mesh filename="package://sucker/meshes/lidar.STL"/>
      </geometry>
    </visual>
    <inertial>
      <mass value="0.1808563355763769"/>
      <origin rpy="-3.141592653589793 0 0" xyz="0.0 -0.00024629 -0.0192734"/>
      <inertia ixx="8.626454773911462e-05" ixy="1.0159520148895485e-20" ixz="2.9084535812218356e-20" iyy="8.446081612680957e-05" iyz="6.36775177103691e-07" izz="0.00012183428513210594"/>
    </inertial>
  </link>
  <joint name="base_link_to_camera" type="fixed">
    <parent link="base_link"/>
    <child link="camera"/>
    <origin rpy="-0.08726646259972501 0 0" xyz="0.5 0.515057 0.604778"/>
  </joint>
  <joint name="base_link_to_wheel_rl" type="continuous">
    <parent link="base_link"/>
    <child link="wheel_rl"/>
    <origin rpy="1.570796326794897 -0.6659692373790911 1.5707963267948966" xyz="0.56 0.47 0.504"/>
    <axis xyz="0 0 1"/>
  </joint>
  <joint name="base_link_to_wheel_fr" type="continuous">
    <parent link="base_link"/>
    <child link="wheel_fr"/>
    <origin rpy="1.570796326794897 0 -1.5707963267948966" xyz="0.441 0.318 0.504"/>
    <axis xyz="0 0 1"/>
  </joint>
  <joint name="base_link_to_wheel_rr" type="continuous">
    <parent link="base_link"/>
    <child link="wheel_rr"/>
    <origin rpy="1.570796326794897 -0.6659692373790911 1.5707963267948966" xyz="0.44 0.47 0.504"/>
    <axis xyz="0 0 1"/>
  </joint>
  <joint name="base_link_to_wheel_fl" type="continuous">
    <parent link="base_link"/>
    <child link="wheel_fl"/>
    <origin rpy="1.570796326794897 0 1.5707963267948966" xyz="0.559 0.318 0.504"/>
    <axis xyz="0 0 1"/>
  </joint>
  <joint name="base_link_to_lidar" type="fixed">
    <parent link="base_link"/>
    <child link="lidar"/>
    <origin rpy="-3.141592653589793 0 0" xyz="0.5 0.435 0.559"/>
  </joint>
</robot>
